{
 "cells": [
  {
   "cell_type": "code",
   "execution_count": 13,
   "metadata": {},
   "outputs": [
    {
     "name": "stdout",
     "output_type": "stream",
     "text": [
      "Unexpected exception formatting exception. Falling back to standard exception\n"
     ]
    },
    {
     "name": "stderr",
     "output_type": "stream",
     "text": [
      "Traceback (most recent call last):\n",
      "  File \"C:\\Users\\user\\AppData\\Roaming\\Python\\Python310\\site-packages\\IPython\\core\\interactiveshell.py\", line 3460, in run_code\n",
      "    exec(code_obj, self.user_global_ns, self.user_ns)\n",
      "  File \"C:\\Users\\user\\AppData\\Local\\Temp\\ipykernel_11936\\4100297568.py\", line 10, in <module>\n",
      "    X = data.drop('Decision', axis=1)\n",
      "  File \"c:\\Users\\user\\AppData\\Local\\Programs\\Python\\Python310\\lib\\site-packages\\pandas\\util\\_decorators.py\", line 317, in wrapper\n",
      "    return func(*args, **kwargs)\n",
      "  File \"c:\\Users\\user\\AppData\\Local\\Programs\\Python\\Python310\\lib\\site-packages\\pandas\\core\\frame.py\", line 5391, in drop\n",
      "    return super().drop(\n",
      "  File \"c:\\Users\\user\\AppData\\Local\\Programs\\Python\\Python310\\lib\\site-packages\\pandas\\util\\_decorators.py\", line 317, in wrapper\n",
      "    return func(*args, **kwargs)\n",
      "  File \"c:\\Users\\user\\AppData\\Local\\Programs\\Python\\Python310\\lib\\site-packages\\pandas\\core\\generic.py\", line 4510, in drop\n",
      "    obj = obj._drop_axis(labels, axis, level=level, errors=errors)\n",
      "  File \"c:\\Users\\user\\AppData\\Local\\Programs\\Python\\Python310\\lib\\site-packages\\pandas\\core\\generic.py\", line 4551, in _drop_axis\n",
      "    new_axis = axis.drop(labels, errors=errors)\n",
      "  File \"c:\\Users\\user\\AppData\\Local\\Programs\\Python\\Python310\\lib\\site-packages\\pandas\\core\\indexes\\base.py\", line 6972, in drop\n",
      "    raise KeyError(f\"{list(labels[mask])} not found in axis\")\n",
      "KeyError: \"['Decision'] not found in axis\"\n",
      "\n",
      "During handling of the above exception, another exception occurred:\n",
      "\n",
      "Traceback (most recent call last):\n",
      "  File \"C:\\Users\\user\\AppData\\Roaming\\Python\\Python310\\site-packages\\IPython\\core\\interactiveshell.py\", line 2057, in showtraceback\n",
      "    stb = self.InteractiveTB.structured_traceback(\n",
      "  File \"C:\\Users\\user\\AppData\\Roaming\\Python\\Python310\\site-packages\\IPython\\core\\ultratb.py\", line 1288, in structured_traceback\n",
      "    return FormattedTB.structured_traceback(\n",
      "  File \"C:\\Users\\user\\AppData\\Roaming\\Python\\Python310\\site-packages\\IPython\\core\\ultratb.py\", line 1177, in structured_traceback\n",
      "    return VerboseTB.structured_traceback(\n",
      "  File \"C:\\Users\\user\\AppData\\Roaming\\Python\\Python310\\site-packages\\IPython\\core\\ultratb.py\", line 1030, in structured_traceback\n",
      "    formatted_exception = self.format_exception_as_a_whole(etype, evalue, etb, number_of_lines_of_context,\n",
      "  File \"C:\\Users\\user\\AppData\\Roaming\\Python\\Python310\\site-packages\\IPython\\core\\ultratb.py\", line 960, in format_exception_as_a_whole\n",
      "    frames.append(self.format_record(record))\n",
      "  File \"C:\\Users\\user\\AppData\\Roaming\\Python\\Python310\\site-packages\\IPython\\core\\ultratb.py\", line 870, in format_record\n",
      "    frame_info.lines, Colors, self.has_colors, lvals\n",
      "  File \"C:\\Users\\user\\AppData\\Roaming\\Python\\Python310\\site-packages\\IPython\\core\\ultratb.py\", line 704, in lines\n",
      "    return self._sd.lines\n",
      "  File \"C:\\Users\\user\\AppData\\Roaming\\Python\\Python310\\site-packages\\stack_data\\utils.py\", line 144, in cached_property_wrapper\n",
      "    value = obj.__dict__[self.func.__name__] = self.func(obj)\n",
      "  File \"C:\\Users\\user\\AppData\\Roaming\\Python\\Python310\\site-packages\\stack_data\\core.py\", line 734, in lines\n",
      "    pieces = self.included_pieces\n",
      "  File \"C:\\Users\\user\\AppData\\Roaming\\Python\\Python310\\site-packages\\stack_data\\utils.py\", line 144, in cached_property_wrapper\n",
      "    value = obj.__dict__[self.func.__name__] = self.func(obj)\n",
      "  File \"C:\\Users\\user\\AppData\\Roaming\\Python\\Python310\\site-packages\\stack_data\\core.py\", line 677, in included_pieces\n",
      "    scope_pieces = self.scope_pieces\n",
      "  File \"C:\\Users\\user\\AppData\\Roaming\\Python\\Python310\\site-packages\\stack_data\\utils.py\", line 144, in cached_property_wrapper\n",
      "    value = obj.__dict__[self.func.__name__] = self.func(obj)\n",
      "  File \"C:\\Users\\user\\AppData\\Roaming\\Python\\Python310\\site-packages\\stack_data\\core.py\", line 614, in scope_pieces\n",
      "    scope_start, scope_end = self.source.line_range(self.scope)\n",
      "  File \"C:\\Users\\user\\AppData\\Roaming\\Python\\Python310\\site-packages\\stack_data\\core.py\", line 178, in line_range\n",
      "    return line_range(self.asttext(), node)\n",
      "  File \"C:\\Users\\user\\AppData\\Roaming\\Python\\Python310\\site-packages\\executing\\executing.py\", line 428, in asttext\n",
      "    self._asttext = ASTText(self.text, tree=self.tree, filename=self.filename)\n",
      "  File \"C:\\Users\\user\\AppData\\Roaming\\Python\\Python310\\site-packages\\asttokens\\asttokens.py\", line 307, in __init__\n",
      "    super(ASTText, self).__init__(source_text, filename)\n",
      "  File \"C:\\Users\\user\\AppData\\Roaming\\Python\\Python310\\site-packages\\asttokens\\asttokens.py\", line 44, in __init__\n",
      "    source_text = six.ensure_text(source_text)\n",
      "AttributeError: module 'six' has no attribute 'ensure_text'\n"
     ]
    }
   ],
   "source": [
    "import pandas as pd\n",
    "from sklearn.tree import DecisionTreeClassifier\n",
    "from sklearn.model_selection import train_test_split\n",
    "from sklearn.metrics import accuracy_score\n",
    "\n",
    "# Load the dataset\n",
    "data = pd.read_csv('Phisicochimi.csv', delimiter='\\t')\n",
    "\n",
    "# Separate features and target variable\n",
    "X = data.drop('Decision', axis=1)\n",
    "y = data['Decision']\n",
    "\n",
    "# Convert string values to numeric\n",
    "y = pd.factorize(y)[0]\n",
    "\n",
    "# Split the dataset into training and testing sets\n",
    "X_train, X_test, y_train, y_test = train_test_split(X, y, test_size=0.2, random_state=42)\n",
    "\n",
    "# Create and train the decision tree classifier\n",
    "classifier = DecisionTreeClassifier()\n",
    "classifier.fit(X_train, y_train)\n",
    "\n",
    "# Make predictions on the test set\n",
    "y_pred = classifier.predict(X_test)\n",
    "\n",
    "# Calculate accuracy\n",
    "accuracy = accuracy_score(y_test, y_pred)\n",
    "print(f\"Accuracy: {accuracy}\")\n",
    "\n",
    "# Example prediction on new data\n",
    "new_data = pd.DataFrame([[3, 11.5, 0.05, 55, 30, 12]], columns=X.columns)\n",
    "predicted_class = classifier.predict(new_data)\n",
    "print(f\"Predicted class: {predicted_class}\")\n",
    "\n",
    "# Save the full output to a file\n",
    "with open('output.txt', 'w') as f:\n",
    "    f.write(str(X))\n",
    "    f.write('\\n\\n')\n",
    "    f.write(str(y))\n",
    "    f.write('\\n\\n')\n",
    "    f.write(str(accuracy))\n",
    "    f.write('\\n\\n')\n",
    "    f.write(str(predicted_class))\n"
   ]
  }
 ],
 "metadata": {
  "kernelspec": {
   "display_name": "Python 3",
   "language": "python",
   "name": "python3"
  },
  "language_info": {
   "codemirror_mode": {
    "name": "ipython",
    "version": 3
   },
   "file_extension": ".py",
   "mimetype": "text/x-python",
   "name": "python",
   "nbconvert_exporter": "python",
   "pygments_lexer": "ipython3",
   "version": "3.10.0"
  },
  "orig_nbformat": 4,
  "vscode": {
   "interpreter": {
    "hash": "fb4569285eef3a3450cb62085a5b1e0da4bce0af555edc33dcf29baf3acc1368"
   }
  }
 },
 "nbformat": 4,
 "nbformat_minor": 2
}
